<?xml version='1.0'?>
<!-- Top level tag-->
<robot name="my_robot" xmlns:xacro="http://www.ros.org/wiki/xacro">

<!-- Include the plugins-->
<xacro:include filename="$(find my_robot)/urdf/my_robot.gazebo" />

  <link name="robot_footprint"></link>

  <joint name="robot_footprint_joint" type="fixed">
    <origin xyz="0 0 0" rpy="0 0 0" />
    <parent link="robot_footprint"/>
    <child link="chassis" />
  </joint>

  <link name='chassis'>
    <pose>0 0 0.1 0 0 0</pose>

    <inertial>
      <mass value="15.0"/>
      <origin xyz="0.0 0 0" rpy=" 0 0 0"/>
      <inertia
          ixx="0.1" ixy="0" ixz="0"
          iyy="0.1" iyz="0"
          izz="0.1"
      />
    </inertial>

    <collision name='collision'>
      <origin xyz="0 0 0" rpy=" 0 0 0"/> 
      <geometry>
        <box size=".4 .2 .1"/>
      </geometry>
    </collision>

    <visual name='chassis_visual'>
      <origin xyz="0 0 0" rpy=" 0 0 0"/>
      <geometry>
        <box size=".4 .2 .1"/>
      </geometry>
      <material name="Red">
        <color rgba ="1.0 0.0 0.0 0.0"/>
      </material>
    </visual>

    <collision name='back_caster_collision'>
      <origin xyz="-0.15 0 -0.05" rpy=" 0 0 0"/>
      <geometry>
        <sphere radius="0.0499"/>
      </geometry>
    </collision>

    <visual name='back_caster_visual'>
      <origin xyz="-0.15 0 -0.05" rpy=" 0 0 0"/>
      <geometry>
        <sphere radius="0.05"/>
      </geometry>
    </visual>

    <collision name='front_caster_collision'>
      <origin xyz="0.15 0 -0.05" rpy=" 0 0 0"/>
      <geometry>
        <sphere radius="0.0499"/>
      </geometry>
    </collision>

    <visual name='front_caster_visual'>
      <origin xyz="0.15 0 -0.05" rpy=" 0 0 0"/>
      <geometry>
        <sphere radius="0.05"/>
      </geometry>
    </visual>
  </link>

  <link name="upper_chassis">
    <inertial>
      <mass value="3.0"/>
      <origin xyz="0.0 0 0" rpy=" 0 0 0"/>
      <inertia
          ixx="0.1" ixy="0" ixz="0"
          iyy="0.1" iyz="0"
          izz="0.1"
      />
    </inertial>

    <collision name='collision'>
      <origin xyz="0 0 0" rpy=" 0 0 0"/> 
      <geometry>
        <box size=".25 .2 .05"/>
      </geometry>
    </collision>

    <visual name='upper_chassis_visual'>
      <origin xyz="0 0 0" rpy=" 0 0 0"/>
      <geometry>
        <box size=".25 .2 .05"/>
      </geometry>
      <material name="Red">
        <color rgba ="1.0 0.0 0.0 0.0"/>
      </material>
    </visual>
  </link>
  
  <joint name="chassis_upper_chassis" type="fixed">
    <origin xyz="-0.075 0 0.075" rpy="0 0 0"/>
    <child link="upper_chassis"/>
    <parent link="chassis"/>
  </joint>
  <!--The wheels and their joints-->
  <link name="left_wheel">

    <visual name="left_wheel_visual">
      <origin xyz="0.0 0.0 0.0" rpy="0.0 1.5707 1.5707"/>
      <geometry>
        <cylinder length="0.05" radius="0.1"/>
      </geometry>
      <material name="Black">
        <color rgba ="0.0 0.0 0.0 0.0"/>
      </material>
    </visual>

    <collision name="left_wheel_collision">
      <origin xyz="0.0 0.0 0.0" rpy="0.0 1.5707 1.5707"/>
      <geometry>
        <cylinder length="0.05" radius="0.1"/>
      </geometry>
    </collision>

    <inertial>
      <origin xyz="0.0 0.0 0.0" rpy="0.0 1.5707 1.5707"/>
      <mass value="5"/>
      <inertia
          ixx="0.1" ixy="0" ixz="0"
          iyy="0.1" iyz="0"
          izz="0.1"
      />
    </inertial>
  </link>

  <joint type="continuous" name="left_wheel_hinge">
    <origin xyz="0 0.15 0" rpy="0 0 0"/>
    <child link="left_wheel"/>
    <parent link="chassis"/>
    <axis xyz="0 1 0" rpy="0 0 0"/>
    <limit effort="10000" velocity="1000"/>
    <dynamics damping="1.0" friction="1.0"/>
  </joint>

  <link name="right_wheel">
    <visual name="right_wheel_visual">
      <origin xyz="0.0 0.0 0.0" rpy="0.0 1.5707 1.5707"/>
      <geometry>
        <cylinder length="0.05" radius="0.1"/>
      </geometry>
      <material name="Red">
       <color rgba="1.0 0.0 0.0 0.0"/>
     </material>
    </visual>

    <collision name="right_wheel_collision">
      <origin xyz="0.0 0.0 0.0" rpy="0.0 1.5707 1.5707"/>
      <geometry>
        <cylinder length="0.05" radius="0.1"/>
      </geometry>
    </collision>

    <inertial>
      <origin xyz="0.0 0.0 0.0" rpy="0.0 1.5707 1.5707"/>
      <mass value="5"/>
      <inertia
          ixx="0.1" ixy="0" ixz="0"
          iyy="0.1" iyz="0"
          izz="0.1"
      />
    </inertial>
  </link>
  
  <joint type="continuous" name="right_wheel_hinge">
    <origin xyz="0 -0.15 0" rpy="0 0 0"/>
    <child link="right_wheel"/>
    <parent link="chassis"/>
    <axis xyz="0 1 0" rpy="0 0 0"/>
    <limit effort="10000" velocity="1000"/>
    <dynamics damping="1.0" friction="1.0"/>
  </joint>

  <!--The camera and its joints-->
  <link name="camera">
    <visual>
      <origin xyz="0.0 0.0 0.0" rpy="0.0 0.0 0.0"/>
      <geometry>
        <box size="0.05 0.05 0.05"/>
      </geometry>
    </visual>

    <collision>
      <origin xyz="0.0 0.0 0.0" rpy="0.0 0.0 0.0"/>
      <geometry>
        <box size="0.05 0.05 0.05"/>
      </geometry>
    </collision>

    <intertial>
      <origin xyz="0.0 0.0 0.0" rpy="0.0 0.0 0.0"/>
      <geometry>
        <box size="0.05 0.05 0.05"/>
      </geometry>
      <inertia
        ixx="1e-6" ixy="0" ixz="0"
        iyy="1e-6" iyz="0"
        izz="1e-6"
      />
    </intertial>
  </link>

  <joint name="camera_joint" type="fixed">
    <origin xyz="0.2 0.0 0.0" rpy="0.0 0.0 0.0"/>
    <axis xyz="0 1 0" rpy="0.0 0.0 0.0"/> 
    <parent link="chassis"/>
    <child link="camera"/>
  </joint>
  
  <link name="hokuyo">
    <visual>
      <origin xyz="0.0 0.0 0.0" rpy="0.0 0.0 0.0"/>
      <geometry>
        <mesh filename="package://my_robot/meshes/hokuyo.dae"/>
      </geometry>   
    </visual>

    <collision>
      <origin xyz="0.0 0.0 0.0" rpy="0.0 0.0 0.0"/>
      <geometry>
        <box size="0.1 0.1 0.1"/>
      </geometry>
    </collision>

    <inertial>
      <origin xyz="0.0 0.0 0.0" rpy="0.0 0.0 0.0"/>
      <mass value="1e-5"/>
      <inertia
        ixx="1e-6" ixy="0.0" ixz="0.0"
        iyy="1e-6" iyz="0.0"
        izz="1e-6"
      /> 
    </inertial>
  </link>
  
  <joint name="hokuyo_joint" type="fixed">
    <origin xyz="0.15 0 0.1" rpy="0.0 0.0 0.0"/>
    <axis xyz="0.0 1.0 0.0" rpy="0.0 0.0 0.0"/>
    <parent link="chassis"/>
    <child link="hokuyo"/>
  </joint>
  <!--Coloring-->
  <!--Chassis-->
  <gazebo reference="chassis">
    <material>Gazebo/Red</material>
  </gazebo>

  <gazebo reference="upper_chassis">
    <material>Gazebo/Red</material>
  </gazebo>

  <!--Wheels-->
  <gazebo reference="right_wheel">
    <material>Gazebo/Black</material>
  </gazebo>

  <gazebo reference="left_wheel">
    <material>Gazebo/Black</material>
  </gazebo>

  <gazebo reference="camera">
    <material>Gazebo/Black</material>
  </gazebo>

</robot>